Lmod has detected the following error: The following module(s) are unknown:
"pytorch/1.4.0" "cuda/10.0.13"

Please check the spelling or version number. Also try "module spider ..."
It is also possible your cache file is out-of-date; it may help to try:
  $ module --ignore-cache load "pytorch/1.4.0" "cuda/10.0.13"



Couldn't import umap
I'm counting gpu's:  1
Means I will train  1  models, with different random seeds
My Devices:  ['cuda:0']
Sampling dataset of 300000 training examples
  0%|          | 0/9 [00:00<?, ?trial/s, best loss=?]                                                     Testing hyperparameters:
  0%|          | 0/9 [00:00<?, ?trial/s, best loss=?]                                                     lr : 0.00354145417156405
  0%|          | 0/9 [00:00<?, ?trial/s, best loss=?]                                                     Trainingdataset:
  0%|          | 0/9 [00:04<?, ?trial/s, best loss=?]                                                     Dataset Crops
    Number of datapoints: 287858
    Root Location: data/Crops
    Reduce: average

  0%|          | 0/9 [00:04<?, ?trial/s, best loss=?]                                                     Using Evaluationdataset:
  0%|          | 0/9 [00:04<?, ?trial/s, best loss=?]                                                     Dataset Crops
    Number of datapoints: 55740
    Root Location: data/Crops
    Reduce: average

  0%|          | 0/9 [00:04<?, ?trial/s, best loss=?]job exception: local variable 'nntype' referenced before assignment

  0%|          | 0/9 [00:04<?, ?trial/s, best loss=?]

-----------------------------------------------------------------------------------------------------------------
TRIAL PROTOCOL:
-----------------------------------------------------------------------------------------------------------------
-----------------------------------------------------------------------------------------------------------------
Traceback (most recent call last):
  File "run_models.py", line 234, in <module>
    max_evals=args.num_search)
  File "/cluster/home/metzgern/.local/lib/python3.7/site-packages/hyperopt/fmin.py", line 482, in fmin
    show_progressbar=show_progressbar,
  File "/cluster/home/metzgern/.local/lib/python3.7/site-packages/hyperopt/base.py", line 686, in fmin
    show_progressbar=show_progressbar,
  File "/cluster/home/metzgern/.local/lib/python3.7/site-packages/hyperopt/fmin.py", line 509, in fmin
    rval.exhaust()
  File "/cluster/home/metzgern/.local/lib/python3.7/site-packages/hyperopt/fmin.py", line 330, in exhaust
    self.run(self.max_evals - n_done, block_until_done=self.asynchronous)
  File "/cluster/home/metzgern/.local/lib/python3.7/site-packages/hyperopt/fmin.py", line 286, in run
    self.serial_evaluate()
  File "/cluster/home/metzgern/.local/lib/python3.7/site-packages/hyperopt/fmin.py", line 165, in serial_evaluate
    result = self.domain.evaluate(spec, ctrl)
  File "/cluster/home/metzgern/.local/lib/python3.7/site-packages/hyperopt/base.py", line 894, in evaluate
    rval = self.fn(pyll_rval)
  File "/cluster/work/igp_psr/metzgern/ODEcrop/latent_ode-my_mod_hparam/lib/training.py", line 127, in construct_and_train_model
    comment = nntype + "_ns:" + str(args.n) + "_ba:" + str(args.batch_size) + "_ode-units:" + str(args.units) + "_gru-uts:" + str(args.gru_units) + "_lats:"+ str(args.latents) + "_rec-lay:" + str(args.rec_layers) + "_solver:" + str(args.ode_method) + "_seed:" +str(args.random_seed) + "_optim:" +str(args.optimizer)
UnboundLocalError: local variable 'nntype' referenced before assignment

During handling of the above exception, another exception occurred:

Traceback (most recent call last):
  File "run_models.py", line 252, in <module>
    hyperopt_summary(trials)
  File "/cluster/work/igp_psr/metzgern/ODEcrop/latent_ode-my_mod_hparam/lib/utils.py", line 798, in hyperopt_summary
    np.sqrt(best_var)*100,
UnboundLocalError: local variable 'best_var' referenced before assignment
