Lmod has detected the following error: The following module(s) are unknown:
"cuda/10.0.13" "pytorch/1.4.0"

Please check the spelling or version number. Also try "module spider ..."
It is also possible your cache file is out-of-date; it may help to try:
  $ module --ignore-cache load "cuda/10.0.13" "pytorch/1.4.0"



Couldn't import umap
I'm counting gpu's:  1
Means I will train  1  models, with different random seeds
My Devices:  ['cuda:0']
Sampling dataset of 300000 training examples
  0%|          | 0/1 [00:00<?, ?trial/s, best loss=?]                                                     Testing hyperparameters:
  0%|          | 0/1 [00:00<?, ?trial/s, best loss=?]                                                     lr : 0.0036331572688296436
  0%|          | 0/1 [00:00<?, ?trial/s, best loss=?]                                                     Trainingdataset:
  0%|          | 0/1 [00:03<?, ?trial/s, best loss=?]                                                     Dataset Crops
    Number of datapoints: 287858
    Root Location: data/Crops
    Reduce: average

  0%|          | 0/1 [00:03<?, ?trial/s, best loss=?]                                                     Using Evaluationdataset:
  0%|          | 0/1 [00:03<?, ?trial/s, best loss=?]                                                     Dataset Crops
    Number of datapoints: 55740
    Root Location: data/Crops
    Reduce: average

  0%|          | 0/1 [00:03<?, ?trial/s, best loss=?]2020-04-15 18:43:32.253200: W tensorflow/stream_executor/platform/default/dso_loader.cc:55] Could not load dynamic library 'libnvinfer.so.6'; dlerror: libnvinfer.so.6: cannot open shared object file: No such file or directory; LD_LIBRARY_PATH: /cluster/apps/lsf/10.1/linux3.10-glibc2.17-x86_64/lib:/cluster/apps/gcc-4.8.5/libpng-1.6.27-d6quyddan2eotsexesxufytusf27xxgz/lib:/cluster/apps/gcc-4.8.5/jpeg-9b-psjvucpx7xwkflb3meatuo6ugdtapkex/lib:/cluster/apps/gcc-4.8.5/nccl-2.4.8-1-xpkpjc3dfz3c5knwctwl5vcut2ahfrwe/lib:/cluster/apps/gcc-4.8.5/cudnn-7.6.4-3ddmfyxxx2gkzhrra44ir3h3ls6yeuwe/lib64:/cluster/apps/gcc-4.8.5/cuda-10.1.243-7tq43deb5x4dbs4oe427w4zszno23q6r/lib64:/cluster/apps/gcc-4.8.5/openblas-0.2.19-w25ydbabttcfa6g76gejjkthcm3xcuv3/lib:/cluster/apps/python/3.7.4/x86_64/lib64
2020-04-15 18:43:32.253340: W tensorflow/stream_executor/platform/default/dso_loader.cc:55] Could not load dynamic library 'libnvinfer_plugin.so.6'; dlerror: libnvinfer_plugin.so.6: cannot open shared object file: No such file or directory; LD_LIBRARY_PATH: /cluster/apps/lsf/10.1/linux3.10-glibc2.17-x86_64/lib:/cluster/apps/gcc-4.8.5/libpng-1.6.27-d6quyddan2eotsexesxufytusf27xxgz/lib:/cluster/apps/gcc-4.8.5/jpeg-9b-psjvucpx7xwkflb3meatuo6ugdtapkex/lib:/cluster/apps/gcc-4.8.5/nccl-2.4.8-1-xpkpjc3dfz3c5knwctwl5vcut2ahfrwe/lib:/cluster/apps/gcc-4.8.5/cudnn-7.6.4-3ddmfyxxx2gkzhrra44ir3h3ls6yeuwe/lib64:/cluster/apps/gcc-4.8.5/cuda-10.1.243-7tq43deb5x4dbs4oe427w4zszno23q6r/lib64:/cluster/apps/gcc-4.8.5/openblas-0.2.19-w25ydbabttcfa6g76gejjkthcm3xcuv3/lib:/cluster/apps/python/3.7.4/x86_64/lib64
2020-04-15 18:43:32.253352: W tensorflow/compiler/tf2tensorrt/utils/py_utils.cc:30] Cannot dlopen some TensorRT libraries. If you would like to use Nvidia GPU with TensorRT, please make sure the missing libraries mentioned above are installed properly.
                                                     runs/expID2295000_TRAINode_ns:300000_ba:700_ode-units:255_gru-uts:100_lats:70_rec-lay:2_solver:dopri5_seed:6001_optim:adamax_stackin:2
  0%|          | 0/1 [00:06<?, ?trial/s, best loss=?]run_models.py --niters 60 -n 300000 -validn 60000 --ode-rnn --ode-type linear --rnn-cell gru --stacking 2 --ode-method dopri5 --random-seed 6001 --num-search 1 --num-seeds 1 --hparams lr

                                                     0.8459813419447435
  0%|          | 0/1 [7:59:47<?, ?trial/s, best loss=?]                                                       {'loss': 0.1540186580552565, 'loss_variance': nan, 'status': 'ok', 'num_seeds': 1, 'best_acc': 0.8459813419447435}
  0%|          | 0/1 [7:59:47<?, ?trial/s, best loss=?]100%|██████████| 1/1 [7:59:47<00:00, 28787.86s/trial, best loss: 0.1540186580552565]100%|██████████| 1/1 [7:59:47<00:00, 28787.86s/trial, best loss: 0.1540186580552565]/cluster/work/igp_psr/metzgern/ODEcrop/latent_ode-my_mod_hparam/lib/training.py:167: RuntimeWarning: invalid value encountered in true_divide
  var_test_acc = sum((abs(Test_acc - mean_test_acc)**2)/(num_seeds-1))

/cluster/work/igp_psr/metzgern/ODEcrop/latent_ode-my_mod_hparam/lib/training.py:170: RuntimeWarning: invalid value encountered in true_divide
  var_best_test_acc = sum((abs(Best_test_acc - mean_best_test_acc)**2)/(num_seeds-1))

/cluster/work/igp_psr/metzgern/ODEcrop/latent_ode-my_mod_hparam/lib/training.py:174: RuntimeWarning: invalid value encountered in true_divide
  var_train_acc = sum((abs(Train_acc - mean_train_acc)**2)/(num_seeds-1))


ODE-RNN  True
Classic-RNN:  False
Stacked layers:  2
ODE-type:  linear
RNN-cell:  gru
defaut adapted LR's!!
Used Optimizer: adamax
Used Ode-Solver dopri5

---------------------------------------------------------------------------------------------------------------------------
TRIAL PROTOCOL:
---------------------------------------------------------------------------------------------------------------------------
Trial: 0001  |  #runs: 1  |  Mean Acc.: 84.598 %  |  Std: nan %  |  Best Acc.: 84.598 %  |  Hparams: {'lr': [0.0036331572688296436]}  |
---------------------------------------------------------------------------------------------------------------------------
Best configuration mean: 84.598 % (+-nan) (best run: 84.598 %) , with Hyperparmeters: {'lr': [0.0036331572688296436]}
---------------------------------------------------------------------------------------------------------------------------
